<?xml version="1.0" encoding="utf-8"?>
<!-- This URDF was automatically created by SolidWorks to URDF Exporter! Originally created by Stephen Brawner (brawner@gmail.com) 
     Commit Version: 1.6.0-4-g7f85cfe  Build Version: 1.6.7995.38578
     For more information, please see http://wiki.ros.org/sw_urdf_exporter -->
<robot
  name="swerve_urdf">
  <link
    name="base_link">
    <inertial>
      <origin
        xyz="2.43555176027144E-15 -2.69867808655455E-12 -0.0140722157893813"
        rpy="0 0 0" />
      <mass
        value="6.28477706893758" />
      <inertia
        ixx="0.00639339578717677"
        ixy="-7.22703370379447E-08"
        ixz="-2.37830826305792E-10"
        iyy="0.0118818754217734"
        iyz="9.7878757982202E-19"
        izz="0.016753490897147" />
    </inertial>
    <visual>
      <origin
        xyz="0 0 0"
        rpy="0 0 0" />
      <geometry>
        <mesh
          filename="package://swerve_urdf/meshes/base_link.STL" />
      </geometry>
      <material
        name="">
        <color
          rgba="0.752941176470588 0.752941176470588 0.752941176470588 1" />
      </material>
    </visual>
    <collision>
      <origin
        xyz="0 0 0"
        rpy="0 0 0" />
      <geometry>
        <mesh
          filename="package://swerve_urdf/meshes/base_link.STL" />
      </geometry>
    </collision>
  </link>
  <link
    name="steer1">
    <inertial>
      <origin
        xyz="-0.000131914075338579 -0.0122200983849754 -0.0416849527366597"
        rpy="0 0 0" />
      <mass
        value="1.11397042751292" />
      <inertia
        ixx="0.000631499796138262"
        ixy="-3.01039870726655E-06"
        ixz="-5.35159180169594E-08"
        iyy="0.000512110896770031"
        iyz="-6.29881109906855E-07"
        izz="0.000793070567248551" />
    </inertial>
    <visual>
      <origin
        xyz="0 0 0"
        rpy="0 0 0" />
      <geometry>
        <mesh
          filename="package://swerve_urdf/meshes/steer1.STL" />
      </geometry>
      <material
        name="">
        <color
          rgba="0.752941176470588 0.752941176470588 0.752941176470588 1" />
      </material>
    </visual>
    <collision>
      <origin
        xyz="0 0 0"
        rpy="0 0 0" />
      <geometry>
        <mesh
          filename="package://swerve_urdf/meshes/steer1.STL" />
      </geometry>
    </collision>
  </link>
  <joint
    name="steer1_joint"
    type="continuous">
    <origin
      xyz="0.177999999999973 -0.177999999999867 0.0115700189392032"
      rpy="0 0 0" />
    <parent
      link="base_link" />
    <child
      link="steer1" />
    <axis
      xyz="0 0 1" />
    <limit
      lower="0"
      upper="0"
      effort="7"
      velocity="40" />
  </joint>
  <link
    name="drive1">
    <inertial>
      <origin
        xyz="1.91334549257127E-06 7.10945191606527E-13 -0.00311266095149038"
        rpy="0 0 0" />
      <mass
        value="0.0930124943189411" />
      <inertia
        ixx="5.68163374977129E-05"
        ixy="2.29831118003764E-14"
        ixz="-3.67740278694652E-09"
        iyy="5.66303681233321E-05"
        iyz="-8.66600737999934E-14"
        izz="8.81040187352088E-05" />
    </inertial>
    <visual>
      <origin
        xyz="0 0 0"
        rpy="0 0 0" />
      <geometry>
        <mesh
          filename="package://swerve_urdf/meshes/drive1.STL" />
      </geometry>
      <material
        name="">
        <color
          rgba="1 1 1 0.35" />
      </material>
    </visual>
    <collision>
      <origin
        xyz="0 0 0"
        rpy="0 0 0" />
      <geometry>
        <mesh
          filename="package://swerve_urdf/meshes/drive1.STL" />
      </geometry>
    </collision>
  </link>
  <joint
    name="drive1_joint"
    type="continuous">
    <origin
      xyz="0 0.0159999999998657 -0.0475700189392033"
      rpy="1.5707963267949 0 3.14159265358979" />
    <parent
      link="steer1" />
    <child
      link="drive1" />
    <axis
      xyz="0 0 1" />
    <limit
      effort="4.5"
      velocity="52" />
  </joint>
  <link
    name="steer2">
    <inertial>
      <origin
        xyz="-0.000131914075338607 -0.0122200983849753 -0.04168495273666"
        rpy="0 0 0" />
      <mass
        value="1.11397042751292" />
      <inertia
        ixx="0.000631499796138263"
        ixy="-3.01039870726682E-06"
        ixz="-5.35159180162629E-08"
        iyy="0.000512110896770031"
        iyz="-6.29881109906678E-07"
        izz="0.000793070567248551" />
    </inertial>
    <visual>
      <origin
        xyz="0 0 0"
        rpy="0 0 0" />
      <geometry>
        <mesh
          filename="package://swerve_urdf/meshes/steer2.STL" />
      </geometry>
      <material
        name="">
        <color
          rgba="0.752941176470588 0.752941176470588 0.752941176470588 1" />
      </material>
    </visual>
    <collision>
      <origin
        xyz="0 0 0"
        rpy="0 0 0" />
      <geometry>
        <mesh
          filename="package://swerve_urdf/meshes/steer2.STL" />
      </geometry>
    </collision>
  </link>
  <joint
    name="steer2_joint"
    type="continuous">
    <origin
      xyz="0.177999999999971 0.178000000000137 0.0115700189392031"
      rpy="0 0 0" />
    <parent
      link="base_link" />
    <child
      link="steer2" />
    <axis
      xyz="0 0 1" />
    <limit
      lower="0"
      upper="0"
      effort="7"
      velocity="40" />
  </joint>
  <link
    name="drive2">
    <inertial>
      <origin
        xyz="-1.91334549204392E-06 -7.12180314721422E-13 -0.00311266095149038"
        rpy="0 0 0" />
      <mass
        value="0.0930124943189411" />
      <inertia
        ixx="5.68163374977129E-05"
        ixy="2.29831097153534E-14"
        ixz="3.67740278743689E-09"
        iyy="5.66303681233321E-05"
        iyz="8.66600625909693E-14"
        izz="8.81040187352087E-05" />
    </inertial>
    <visual>
      <origin
        xyz="0 0 0"
        rpy="0 0 0" />
      <geometry>
        <mesh
          filename="package://swerve_urdf/meshes/drive2.STL" />
      </geometry>
      <material
        name="">
        <color
          rgba="1 1 1 0.35" />
      </material>
    </visual>
    <collision>
      <origin
        xyz="0 0 0"
        rpy="0 0 0" />
      <geometry>
        <mesh
          filename="package://swerve_urdf/meshes/drive2.STL" />
      </geometry>
    </collision>
  </link>
  <joint
    name="drive2_joint"
    type="continuous">
    <origin
      xyz="0 0.0159999999998658 -0.0475700189392043"
      rpy="1.5707963267949 0 3.14159265358978" />
    <parent
      link="steer2" />
    <child
      link="drive2" />
    <axis
      xyz="0 0 1" />
    <limit
      effort="4.5"
      velocity="52" />
  </joint>
  <link
    name="steer3">
    <inertial>
      <origin
        xyz="-0.000131914075338579 -0.0122200983849753 -0.04168495273666"
        rpy="0 0 0" />
      <mass
        value="1.11397042751292" />
      <inertia
        ixx="0.000631499796138262"
        ixy="-3.01039870726774E-06"
        ixz="-5.35159180162559E-08"
        iyy="0.000512110896770031"
        iyz="-6.29881109906853E-07"
        izz="0.000793070567248551" />
    </inertial>
    <visual>
      <origin
        xyz="0 0 0"
        rpy="0 0 0" />
      <geometry>
        <mesh
          filename="package://swerve_urdf/meshes/steer3.STL" />
      </geometry>
      <material
        name="">
        <color
          rgba="0.752941176470588 0.752941176470588 0.752941176470588 1" />
      </material>
    </visual>
    <collision>
      <origin
        xyz="0 0 0"
        rpy="0 0 0" />
      <geometry>
        <mesh
          filename="package://swerve_urdf/meshes/steer3.STL" />
      </geometry>
    </collision>
  </link>
  <joint
    name="steer3_joint"
    type="continuous">
    <origin
      xyz="-0.178 0.178 0.01157"
      rpy="0 0 0" />
    <parent
      link="base_link" />
    <child
      link="steer3" />
    <axis
      xyz="0 0 1" />
    <limit
      lower="0"
      upper="0"
      effort="7"
      velocity="40" />
  </joint>
  <link
    name="drive3">
    <inertial>
      <origin
        xyz="-1.91334549201616E-06 -7.1384564925836E-13 -0.00311266095149038"
        rpy="0 0 0" />
      <mass
        value="0.0930124943189412" />
      <inertia
        ixx="5.6816337497713E-05"
        ixy="2.29831097528819E-14"
        ixz="3.67740278743983E-09"
        iyy="5.66303681233322E-05"
        iyz="8.66600626136057E-14"
        izz="8.81040187352089E-05" />
    </inertial>
    <visual>
      <origin
        xyz="0 0 0"
        rpy="0 0 0" />
      <geometry>
        <mesh
          filename="package://swerve_urdf/meshes/drive3.STL" />
      </geometry>
      <material
        name="">
        <color
          rgba="1 1 1 0.35" />
      </material>
    </visual>
    <collision>
      <origin
        xyz="0 0 0"
        rpy="0 0 0" />
      <geometry>
        <mesh
          filename="package://swerve_urdf/meshes/drive3.STL" />
      </geometry>
    </collision>
  </link>
  <joint
    name="drive3_joint"
    type="continuous">
    <origin
      xyz="0 0.016 -0.04757"
      rpy="1.5708 0 3.1416" />
    <parent
      link="steer3" />
    <child
      link="drive3" />
    <axis
      xyz="0 0 1" />
    <limit
      effort="4.5"
      velocity="52" />
  </joint>
  <link
    name="steer4">
    <inertial>
      <origin
        xyz="-0.000131914075338607 -0.0122200983849752 -0.04168495273666"
        rpy="0 0 0" />
      <mass
        value="1.11397042751292" />
      <inertia
        ixx="0.000631499796138263"
        ixy="-3.01039870726789E-06"
        ixz="-5.3515918016253E-08"
        iyy="0.000512110896770031"
        iyz="-6.2988110990681E-07"
        izz="0.000793070567248552" />
    </inertial>
    <visual>
      <origin
        xyz="0 0 0"
        rpy="0 0 0" />
      <geometry>
        <mesh
          filename="package://swerve_urdf/meshes/steer4.STL" />
      </geometry>
      <material
        name="">
        <color
          rgba="0.752941176470588 0.752941176470588 0.752941176470588 1" />
      </material>
    </visual>
    <collision>
      <origin
        xyz="0 0 0"
        rpy="0 0 0" />
      <geometry>
        <mesh
          filename="package://swerve_urdf/meshes/steer4.STL" />
      </geometry>
    </collision>
  </link>
  <joint
    name="steer4_joint"
    type="continuous">
    <origin
      xyz="-0.178000000000025 -0.17799999999987 0.0115700189392049"
      rpy="0 0 0" />
    <parent
      link="base_link" />
    <child
      link="steer4" />
    <axis
      xyz="0 0 1" />
    <limit
      lower="0"
      upper="0"
      effort="7"
      velocity="40" />
  </joint>
  <link
    name="drive4">
    <inertial>
      <origin
        xyz="1.91334549240474E-06 7.10272118897848E-13 -0.0031126609514904"
        rpy="0 0 0" />
      <mass
        value="0.093012494318941" />
      <inertia
        ixx="5.68163374977129E-05"
        ixy="2.29831098766692E-14"
        ixz="-3.67740278665974E-09"
        iyy="5.6630368123332E-05"
        iyz="-8.66600524254316E-14"
        izz="8.81040187352087E-05" />
    </inertial>
    <visual>
      <origin
        xyz="0 0 0"
        rpy="0 0 0" />
      <geometry>
        <mesh
          filename="package://swerve_urdf/meshes/drive4.STL" />
      </geometry>
      <material
        name="">
        <color
          rgba="1 1 1 0.35" />
      </material>
    </visual>
    <collision>
      <origin
        xyz="0 0 0"
        rpy="0 0 0" />
      <geometry>
        <mesh
          filename="package://swerve_urdf/meshes/drive4.STL" />
      </geometry>
    </collision>
  </link>
  <joint
    name="drive4_joint"
    type="continuous">
    <origin
      xyz="0 0.0159999999998658 -0.0475700189392043"
      rpy="1.5707963267949 0 3.14159265358977" />
    <parent
      link="steer4" />
    <child
      link="drive4" />
    <axis
      xyz="0 0 1" />
    <limit
      effort="4.5"
      velocity="52" />
  </joint>
</robot>