<?xml version="1.0" encoding="utf-8"?>
<!-- This URDF was automatically created by SolidWorks to URDF Exporter! Originally created by Stephen Brawner (brawner@gmail.com) 
     Commit Version: 1.6.0-4-g7f85cfe  Build Version: 1.6.7995.38578
     For more information, please see http://wiki.ros.org/sw_urdf_exporter -->
<robot
  name="URDF">
  <link
    name="base_link">
    <inertial>
      <origin
        xyz="7.94331267428561E-12 7.94520005342747E-12 0.0818008501965235"
        rpy="0 0 0" />
      <mass
        value="2.13452082267233" />
      <inertia
        ixx="0.00505023124392984"
        ixy="-8.80914265662662E-18"
        ixz="2.37830826519254E-10"
        iyy="0.00505023124392984"
        iyz="-2.37830827423825E-10"
        izz="0.0100179487102063" />
    </inertial>
    <visual>
      <origin
        xyz="0 0 0"
        rpy="0 0 0" />
      <geometry>
        <mesh
          filename="package://URDF/meshes/base_link.STL" />
      </geometry>
      <material
        name="">
        <color
          rgba="0.898039215686275 0.917647058823529 0.929411764705882 1" />
      </material>
    </visual>
    <collision>
      <origin
        xyz="0 0 0"
        rpy="0 0 0" />
      <geometry>
        <mesh
          filename="package://URDF/meshes/base_link.STL" />
      </geometry>
    </collision>
  </link>
  <link
    name="steer1">
    <inertial>
      <origin
        xyz="0.17805 0.16576 0.045793"
        rpy="0 0 0" />
      <mass
        value="1.1119" />
      <inertia
        ixx="0.00063155"
        ixy="-1.2629E-06"
        ixz="-4.4296E-08"
        iyy="0.00051204"
        iyz="-6.306E-07"
        izz="0.00079305" />
    </inertial>
    <visual>
      <origin
        xyz="0 0 0"
        rpy="0 0 0" />
      <geometry>
        <mesh
          filename="package://URDF/meshes/steer1.STL" />
      </geometry>
      <material
        name="">
        <color
          rgba="1 1 1 0.35" />
      </material>
    </visual>
    <collision>
      <origin
        xyz="0 0 0"
        rpy="0 0 0" />
      <geometry>
        <mesh
          filename="package://URDF/meshes/steer1.STL" />
      </geometry>
    </collision>
  </link>
  <joint
    name="steer1_joint"
    type="revolute">
    <origin
      xyz="0 0 0"
      rpy="0 0 0" />
    <parent
      link="base_link" />
    <child
      link="steer1" />
    <axis
      xyz="0 0 1" />
    <limit
      lower="0"
      upper="0"
      effort="14"
      velocity="40" />
  </joint>
  <link
    name="drive1">
    <inertial>
      <origin
        xyz="-0.14877 -0.04757 -0.003727"
        rpy="0 0 0" />
      <mass
        value="0.093012" />
      <inertia
        ixx="5.6816E-05"
        ixy="2.2945E-14"
        ixz="-3.6774E-09"
        iyy="5.663E-05"
        iyz="-8.7736E-14"
        izz="8.8104E-05" />
    </inertial>
    <visual>
      <origin
        xyz="0 0 0"
        rpy="0 0 0" />
      <geometry>
        <mesh
          filename="package://URDF/meshes/drive1.STL" />
      </geometry>
      <material
        name="">
        <color
          rgba="1 1 1 0.35" />
      </material>
    </visual>
    <collision>
      <origin
        xyz="0 0 0"
        rpy="0 0 0" />
      <geometry>
        <mesh
          filename="package://URDF/meshes/drive1.STL" />
      </geometry>
    </collision>
  </link>
  <joint
    name="drive1_joint"
    type="continuous">
    <origin
      xyz="0.029 0.19244 0.08757"
      rpy="1.5708 0 -3.127" />
    <parent
      link="steer1" />
    <child
      link="drive1" />
    <axis
      xyz="0 0 -1" />
    <limit
      effort="4.5"
      velocity="52" />
  </joint>
  <link
    name="steer2">
    <inertial>
      <origin
        xyz="0.165756272867722 -0.178046942564116 0.0457933558711005"
        rpy="0 0 0" />
      <mass
        value="1.1118772178264" />
      <inertia
        ixx="0.000512037355922977"
        ixy="1.26288825588275E-06"
        ixz="-6.30596556577934E-07"
        iyy="0.000631551289156068"
        iyz="4.42963468371104E-08"
        izz="0.000793052091848933" />
    </inertial>
    <visual>
      <origin
        xyz="0 0 0"
        rpy="0 0 0" />
      <geometry>
        <mesh
          filename="package://URDF/meshes/steer2.STL" />
      </geometry>
      <material
        name="">
        <color
          rgba="1 1 1 0.35" />
      </material>
    </visual>
    <collision>
      <origin
        xyz="0 0 0"
        rpy="0 0 0" />
      <geometry>
        <mesh
          filename="package://URDF/meshes/steer2.STL" />
      </geometry>
    </collision>
  </link>
  <joint
    name="steer2_joint"
    type="revolute">
    <origin
      xyz="0 0 0"
      rpy="0 0 0" />
    <parent
      link="base_link" />
    <child
      link="steer2" />
    <axis
      xyz="0 0 1" />
    <limit
      lower="0"
      upper="0"
      effort="14"
      velocity="40" />
  </joint>
  <link
    name="drive2">
    <inertial>
      <origin
        xyz="-0.148771117523335 -0.0475700189380724 -0.00372703536676822"
        rpy="0 0 0" />
      <mass
        value="0.0930124941681603" />
      <inertia
        ixx="5.68163374839874E-05"
        ixy="2.29453387751653E-14"
        ixz="-3.67739933063103E-09"
        iyy="5.66303681074938E-05"
        iyz="-8.77355248562714E-14"
        izz="8.81040187330934E-05" />
    </inertial>
    <visual>
      <origin
        xyz="0 0 0"
        rpy="0 0 0" />
      <geometry>
        <mesh
          filename="package://URDF/meshes/drive2.STL" />
      </geometry>
      <material
        name="">
        <color
          rgba="1 1 1 0.35" />
      </material>
    </visual>
    <collision>
      <origin
        xyz="0 0 0"
        rpy="0 0 0" />
      <geometry>
        <mesh
          filename="package://URDF/meshes/drive2.STL" />
      </geometry>
    </collision>
  </link>
  <joint
    name="drive2_joint"
    type="continuous">
    <origin
      xyz="0.19244 -0.029 0.08757"
      rpy="1.5708 0 1.5854" />
    <parent
      link="steer2" />
    <child
      link="drive2" />
    <axis
      xyz="0 0 -1" />
    <limit
      effort="4.5"
      velocity="52" />
  </joint>
  <link
    name="steer3">
    <inertial>
      <origin
        xyz="-0.178046942564116 -0.165756272867729 0.0457933558711005"
        rpy="0 0 0" />
      <mass
        value="1.1118772178264" />
      <inertia
        ixx="0.000631551289156068"
        ixy="-1.26288825588178E-06"
        ixz="4.42963468371406E-08"
        iyy="0.000512037355922978"
        iyz="6.30596556577819E-07"
        izz="0.000793052091848933" />
    </inertial>
    <visual>
      <origin
        xyz="0 0 0"
        rpy="0 0 0" />
      <geometry>
        <mesh
          filename="package://URDF/meshes/steer3.STL" />
      </geometry>
      <material
        name="">
        <color
          rgba="1 1 1 0.35" />
      </material>
    </visual>
    <collision>
      <origin
        xyz="0 0 0"
        rpy="0 0 0" />
      <geometry>
        <mesh
          filename="package://URDF/meshes/steer3.STL" />
      </geometry>
    </collision>
  </link>
  <joint
    name="steer3_joint"
    type="revolute">
    <origin
      xyz="0 0 0"
      rpy="0 0 0" />
    <parent
      link="base_link" />
    <child
      link="steer3" />
    <axis
      xyz="0 0 1" />
    <limit
      lower="0"
      upper="0"
      effort="14"
      velocity="40" />
  </joint>
  <link
    name="drive3">
    <inertial>
      <origin
        xyz="-0.148771117523335 -0.0475700189380724 -0.00372703536676822"
        rpy="0 0 0" />
      <mass
        value="0.0930124941681606" />
      <inertia
        ixx="5.68163374839876E-05"
        ixy="2.29453389579205E-14"
        ixz="-3.67739933065824E-09"
        iyy="5.6630368107494E-05"
        iyz="-8.77355362228996E-14"
        izz="8.81040187330936E-05" />
    </inertial>
    <visual>
      <origin
        xyz="0 0 0"
        rpy="0 0 0" />
      <geometry>
        <mesh
          filename="package://URDF/meshes/drive3.STL" />
      </geometry>
      <material
        name="">
        <color
          rgba="1 1 1 0.35" />
      </material>
    </visual>
    <collision>
      <origin
        xyz="0 0 0"
        rpy="0 0 0" />
      <geometry>
        <mesh
          filename="package://URDF/meshes/drive3.STL" />
      </geometry>
    </collision>
  </link>
  <joint
    name="drive3_joint"
    type="continuous">
    <origin
      xyz="-0.029 -0.19244 0.08757"
      rpy="1.5708 0 0.014628" />
    <parent
      link="steer3" />
    <child
      link="drive3" />
    <axis
      xyz="0 0 -1" />
    <limit
      effort="4.5"
      velocity="52" />
  </joint>
  <link
    name="steer4">
    <inertial>
      <origin
        xyz="-0.165756272867732 0.178046942564112 0.0457933558711005"
        rpy="0 0 0" />
      <mass
        value="1.1118772178264" />
      <inertia
        ixx="0.000512037355922976"
        ixy="1.26288825588161E-06"
        ixz="6.30596556577833E-07"
        iyy="0.000631551289156068"
        iyz="-4.42963468371611E-08"
        izz="0.000793052091848931" />
    </inertial>
    <visual>
      <origin
        xyz="0 0 0"
        rpy="0 0 0" />
      <geometry>
        <mesh
          filename="package://URDF/meshes/steer4.STL" />
      </geometry>
      <material
        name="">
        <color
          rgba="1 1 1 0.35" />
      </material>
    </visual>
    <collision>
      <origin
        xyz="0 0 0"
        rpy="0 0 0" />
      <geometry>
        <mesh
          filename="package://URDF/meshes/steer4.STL" />
      </geometry>
    </collision>
  </link>
  <joint
    name="steer4_joint"
    type="revolute">
    <origin
      xyz="0 0 0"
      rpy="0 0 0" />
    <parent
      link="base_link" />
    <child
      link="steer4" />
    <axis
      xyz="0 0 1" />
    <limit
      lower="0"
      upper="0"
      effort="14"
      velocity="40" />
  </joint>
  <link
    name="drive4">
    <inertial>
      <origin
        xyz="-0.148771117523335 -0.0475700189380724 -0.00372703536676821"
        rpy="0 0 0" />
      <mass
        value="0.0930124941681607" />
      <inertia
        ixx="5.68163374839877E-05"
        ixy="2.29453389187193E-14"
        ixz="-3.677399330653E-09"
        iyy="5.66303681074941E-05"
        iyz="-8.77355429679947E-14"
        izz="8.81040187330937E-05" />
    </inertial>
    <visual>
      <origin
        xyz="0 0 0"
        rpy="0 0 0" />
      <geometry>
        <mesh
          filename="package://URDF/meshes/drive4.STL" />
      </geometry>
      <material
        name="">
        <color
          rgba="1 1 1 0.35" />
      </material>
    </visual>
    <collision>
      <origin
        xyz="0 0 0"
        rpy="0 0 0" />
      <geometry>
        <mesh
          filename="package://URDF/meshes/drive4.STL" />
      </geometry>
    </collision>
  </link>
  <joint
    name="drive4_joint"
    type="continuous">
    <origin
      xyz="-0.19244 0.029 0.08757"
      rpy="1.5708 0 -1.5562" />
    <parent
      link="steer4" />
    <child
      link="drive4" />
    <axis
      xyz="0 0 -1" />
    <limit
      effort="4.5"
      velocity="52" />
  </joint>
</robot>